<sdf version='1.6'>
  <world name='default'>
    <include>
      <uri>model://ground_plane</uri>
    </include>
    <include>
      <uri>model://sun</uri>
    </include>
    <include>
      <uri>model://hinged_door</uri>
      <pose>0 5 0 0 0 0</pose>
    </include>
    <model name="hinged_door_2">
      <link name="frame">
        <pose>0.06 -0.0005 0 0 0 0</pose>
        <collision name="collision_1">
          <pose>-0.025145 -0.03429 1.0541 0 0 0</pose>
          <geometry>
            <box>
              <size>0.05029 0.06858 2.10820</size>
            </box>
          </geometry>
        </collision>
        <collision name="collision_2">
          <pose>-0.025145 0.95631 1.0541 0 0 0</pose>
          <geometry>
            <box>
              <size>0.05029 0.06858 2.10820</size>
            </box>
          </geometry>
        </collision>
        <collision name="collision_3">
          <pose>-0.0251450 0.46482 2.07137 0 0 0</pose>
          <geometry>
            <box>
              <size>0.05029 0.92964 0.07366</size>
            </box>
          </geometry>
        </collision>
        <visual name="visual">
          <pose>0 -0.06858 0 0 0 0</pose>
          <geometry>
            <mesh>
              <uri>model://hinged_door/meshes/frame.dae</uri>
            </mesh>
          </geometry>
        </visual>
      </link>
      <link name="door">
        <pose>-0.0 0.000 2.040 3.14159 0 1.57</pose>
        <inertial>
          <mass>41.3256</mass>
          <pose>0.4569 0.0349 1.016 0 0 0</pose>
          <inertia>
            <ixx>14.2053</ixx>
            <ixy>0.0004</ixy>
            <ixz>0.0000</ixz>
            <iyy>17.1997</iyy>
            <iyz>0.0000</iyz>
            <izz>3.0298</izz>
          </inertia>
        </inertial>
        <collision name="collision">
          <pose>0.4569 0.0349 1.016 0 0 0</pose>
          <geometry>
            <box>
              <size>0.9144 0.04445 2.032</size>
            </box>
          </geometry>
        </collision>
        <visual name="visual">
          <pose>0 -0.06858 0 0 0 0</pose>
          <geometry>
            <mesh>
              <uri>model://hinged_door/meshes/door.dae</uri>
            </mesh>
          </geometry>
          <material>
          <script>
            <uri>file://media/materials/scripts/Gazebo.material</uri>
            <name>Gazebo/Yellow</name>
          </script>
          </material>
        </visual>
      </link>
      <link name="handles">
        <pose>0.0 0.8 1.05 0 3.14 1.57</pose>
        <collision name="handle1_collision">
          <pose>0.015 -0.015 0 -1.57 0 0</pose>
          <geometry>
            <mesh>
              <uri>model://door_handle/meshes/handle.dae</uri>
            </mesh>
          </geometry>
        </collision>
        <visual name="handle1_visual">
          <pose>0.015 -0.015 0 -1.57 0 0</pose>
          <geometry>
            <mesh>
              <uri>model://door_handle/meshes/handle.dae</uri>
            </mesh>
          </geometry>
        </visual>
        <collision name="handle2_collision">
          <pose>0.015 -0.055 0 1.57 0 0</pose>
          <geometry>
            <mesh>
              <uri>model://door_handle/meshes/handle.dae</uri>
            </mesh>
          </geometry>
        </collision>
        <visual name="handle2_visual">
          <pose>0.015 -0.055 0 1.57 0 0</pose>
          <geometry>
            <mesh>
              <uri>model://door_handle/meshes/handle.dae</uri>
            </mesh>
          </geometry>
        </visual>
      </link>
      <joint name="handle" type="revolute">
        <parent>door</parent>
        <child>handles</child>
        <pose>0.015 0 0 0 0 0</pose>
        <axis>
          <xyz>1 0 0</xyz>
          <limit>
            <lower>0</lower>
            <upper>1.58</upper>
          </limit>
          <dynamics>
            <damping>0</damping>
            <friction>5.0</friction>
          </dynamics>
          <use_parent_model_frame>true</use_parent_model_frame>
        </axis>
      </joint>
      <joint name="hinge" type="revolute">
        <parent>frame</parent>
        <child>door</child>
        <axis>
          <xyz>0 0 1</xyz>
          <limit>
            <lower>0</lower>
            <upper>1.58</upper>
          </limit>
          <dynamics>
            <damping>0.1</damping>
            <friction>3.0</friction>
          </dynamics>
          <use_parent_model_frame>true</use_parent_model_frame>
        </axis>
      </joint>
      <joint name="world_joint" type="fixed">
        <child>frame</child>
        <parent>world</parent>
        <axis>
          <limit>
            <lower>0</lower>
            <upper>0</upper>
          </limit>
          <xyz>0 1 0</xyz>
          <dynamics>
            <damping>0</damping>
          </dynamics>
          <use_parent_model_frame>true</use_parent_model_frame>
        </axis>
      </joint>
    </model>
    <model name="walls">
      <static>true</static>
      <link name="wall_1">
        <collision name="wall_1_collision">
          <pose>0.03 2.96621 1.05342 0 0 0</pose>
          <geometry>
            <box>
              <size>0.1 3.93142 2.10684</size>
            </box>
          </geometry>
        </collision>
        <visual name="wall_1_visual">
          <pose>0.03 2.96621 1.05342 0 0 0</pose>
          <geometry>
            <box>
              <size>0.1 3.93142 2.10684</size>
            </box>
          </geometry>
          <material>
            <script>
              <uri>file://media/materials/scripts/Gazebo.material</uri>
              <name>Gazebo/White</name>
            </script>
          </material>
        </visual>
      </link>
      <link name="wall_2">
        <collision name="wall_2_collision">
          <pose>0.03 -1.53429 1.05342 0 0 0</pose>
          <geometry>
            <box>
              <size>0.1 2.93142 2.10684</size>
            </box>
          </geometry>
        </collision>
        <visual name="wall_2_visual">
          <pose>0.03 -1.53429 1.05342 0 0 0</pose>
          <geometry>
            <box>
              <size>0.1 2.93142 2.10684</size>
            </box>
          </geometry>
          <material>
            <script>
              <uri>file://media/materials/scripts/Gazebo.material</uri>
              <name>Gazebo/White</name>
            </script>
          </material>
        </visual>
      </link>
      <link name="wall_3">
        <collision name="wall_3_collision">
          <pose>0.03 7.5 1.05342 0 0 0</pose>
          <geometry>
            <box>
              <size>0.1 3 2.10684</size>
            </box>
          </geometry>
        </collision>
        <visual name="wall_3_visual">
          <pose>0.03 7.5 1.05342 0 0 0</pose>
          <geometry>
            <box>
              <size>0.1 3 2.10684</size>
            </box>
          </geometry>
          <material>
            <script>
              <uri>file://media/materials/scripts/Gazebo.material</uri>
              <name>Gazebo/White</name>
            </script>
          </material>
        </visual>
      </link>
      <link name="wall_4">
        <collision name="wall_4_collision">
          <pose>0.03 3 2.30684 0 0 0</pose>
          <geometry>
            <box>
              <size>0.1 12 0.4</size>
            </box>
          </geometry>
        </collision>
        <visual name="wall_4_visual">
          <pose>0.03 3 2.30684 0 0 0</pose>
          <geometry>
            <box>
              <size>0.1 12 0.4</size>
            </box>
          </geometry>
          <material>
            <script>
              <uri>file://media/materials/scripts/Gazebo.material</uri>
              <name>Gazebo/White</name>
            </script>
          </material>
        </visual>
      </link>
      <link name="wall_5">
        <collision name="wall_5_collision">
          <pose>5.04 -2.95 1.25342 0 0 0</pose>
          <geometry>
            <box>
              <size>9.92 0.1 2.50684</size>
            </box>
          </geometry>
        </collision>
        <visual name="wall_5_visual">
          <pose>5.04 -2.95 1.25342 0 0 0</pose>
          <geometry>
            <box>
              <size>9.92 0.1 2.50684</size>
            </box>
          </geometry>
          <material>
            <script>
              <uri>file://media/materials/scripts/Gazebo.material</uri>
              <name>Gazebo/White</name>
            </script>
          </material>
        </visual>
      </link>
      <link name="wall_6">
        <collision name="wall_6_collision">
          <pose>5.04 8.95 1.25342 0 0 0</pose>
          <geometry>
            <box>
              <size>9.92 0.1 2.50684</size>
            </box>
          </geometry>
        </collision>
        <visual name="wall_6_visual">
          <pose>5.04 8.95 1.25342 0 0 0</pose>
          <geometry>
            <box>
              <size>9.92 0.1 2.50684</size>
            </box>
          </geometry>
          <material>
            <script>
              <uri>file://media/materials/scripts/Gazebo.material</uri>
              <name>Gazebo/White</name>
            </script>
          </material>
        </visual>
      </link>
      <link name="wall_7">
        <collision name="wall_7_collision">
          <pose>9.95 3 1.25342 0 0 0</pose>
          <geometry>
            <box>
              <size>0.1 11.8 2.50684</size>
            </box>
          </geometry>
        </collision>
        <visual name="wall_7_visual">
          <pose>9.95 3 1.25342 0 0 0</pose>
          <geometry>
            <box>
              <size>0.1 11.8 2.50684</size>
            </box>
          </geometry>
          <material>
            <script>
              <uri>file://media/materials/scripts/Gazebo.material</uri>
              <name>Gazebo/PaintedWall</name>
            </script>
          </material>
        </visual>
      </link>
      <link name="socket_1">
        <collision name="socket_1_collision">
          <pose>9.895 1 0.3 0 0 0</pose>
          <geometry>
            <box>
              <size>0.01 0.06 0.1</size>
            </box>
          </geometry>
        </collision>
        <visual name="socket_1_visual">
          <pose>9.895 1 0.3 0 0 0</pose>
          <geometry>
            <box>
              <size>0.01 0.06 0.1</size>
            </box>
          </geometry>
          <material>
            <script>
              <uri>file://media/materials/scripts/texture.material</uri>
              <name>dor_gazebo/socket</name>
            </script>
          </material>
        </visual>
      </link>
      <link name="socket_2">
        <collision name="socket_2_collision">
          <pose>9.895 5 0.3 0 0 0</pose>
          <geometry>
            <box>
              <size>0.01 0.06 0.1</size>
            </box>
          </geometry>
        </collision>
        <visual name="socket_2_visual">
          <pose>9.895 5 0.3 0 0 0</pose>
          <geometry>
            <box>
              <size>0.01 0.06 0.1</size>
            </box>
          </geometry>
          <material>
            <script>
              <uri>file://media/materials/scripts/texture.material</uri>
              <name>dor_gazebo/socket</name>
            </script>
          </material>
        </visual>
      </link>
      <link name="wall_8">
        <collision name="wall_8_collision">
          <pose>-3.05 3.0 1.25342 0 0 0</pose>
          <geometry>
            <box>
              <size>0.1 12 2.50684</size>
            </box>
          </geometry>
        </collision>
        <visual name="wall_8_visual">
          <pose>-3.05 3.0 1.25342 0 0 00</pose>
          <geometry>
            <box>
              <size>0.1 12 2.50684</size>
            </box>
          </geometry>
          <material>
            <script>
              <uri>file://media/materials/scripts/Gazebo.material</uri>
              <name>Gazebo/White</name>
            </script>
          </material>
        </visual>
      </link>
    </model>
    <model name="obstacles">
      <static>true</static>
      <link name="obstacle_1">
        <collision name="obstacle_1_collision">
          <pose>5.0 3.0 0.5 0 0 0</pose>
          <geometry>
            <box>
              <size>1.0 1.0 1.0</size>
            </box>
          </geometry>
        </collision>
        <visual name="obstacle_1_visual">
          <pose>5.0 3.0 0.5 0 0 0</pose>
          <geometry>
            <box>
              <size>1.0 1.0 1.0</size>
            </box>
          </geometry>
          <material>
            <script>
              <uri>file://media/materials/scripts/Gazebo.material</uri>
              <name>Gazebo/Wood</name>
            </script>
          </material>
        </visual>
      </link>
      <link name="obstacle_2">
        <collision name="obstacle_2_collision">
          <pose>7.0 -1.0 0.5 0 0 0</pose>
          <geometry>
            <box>
              <size>1.0 1.0 1.0</size>
            </box>
          </geometry>
        </collision>
        <visual name="obstacle_2_visual">
          <pose>7.0 -1.0 0.5 0 0 0</pose>
          <geometry>
            <box>
              <size>1.0 1.0 1.0</size>
            </box>
          </geometry>
          <material>
            <script>
              <uri>file://media/materials/scripts/Gazebo.material</uri>
              <name>Gazebo/Wood</name>
            </script>
          </material>
        </visual>
      </link>
      <link name="obstacle_3">
        <collision name="obstacle_3_collision">
          <pose>2.0 8.0 0.5 0 0 0</pose>
          <geometry>
            <box>
              <size>1.0 1.0 1.0</size>
            </box>
          </geometry>
        </collision>
        <visual name="obstacle_3_visual">
          <pose>2.0 8.0 0.5 0 0 0</pose>
          <geometry>
            <box>
              <size>1.0 1.0 1.0</size>
            </box>
          </geometry>
          <material>
            <script>
              <uri>file://media/materials/scripts/Gazebo.material</uri>
              <name>Gazebo/Wood</name>
            </script>
          </material>
        </visual>
      </link>
      <link name="obstacle_4">
        <collision name="obstacle_4_collision">
          <pose>6.0 7.0 0.2 0 0 0</pose>
          <geometry>
            <box>
              <size>0.6 0.6 0.4</size>
            </box>
          </geometry>
        </collision>
        <visual name="obstacle_4_visual">
          <pose>6.0 7.0 0.2 0 0 0</pose>
          <geometry>
            <box>
                <size>0.6 0.6 0.4</size>
            </box>
          </geometry>
          <material>
          <script>
            <uri>file://media/materials/scripts/Gazebo.material</uri>
            <name>Gazebo/Black</name>
          </script>
          </material>
        </visual>
      </link>
      <link name="obstacle_5">
        <collision name="obstacle_5_collision">
          <pose>8.0 4.0 0.25 0 0 0</pose>
          <geometry>
            <cylinder>
              <radius>0.3</radius>
              <length>0.5</length>
            </cylinder>
          </geometry>
        </collision>
        <visual name="obstacle_5_visual">
          <pose>8.0 4.0 0.25 0 0 0</pose>
          <geometry>
            <cylinder>
              <radius>0.3</radius>
              <length>0.5</length>
            </cylinder>
          </geometry>
          <material>
          <script>
            <uri>file://media/materials/scripts/Gazebo.material</uri>
            <name>Gazebo/Black</name>
          </script>
          </material>
        </visual>
      </link>
      <link name="obstacle_6">
        <collision name="obstacle_6_collision">
          <pose>-2.85 -1 0.25 0 0 0</pose>
          <geometry>
            <cylinder>
              <radius>0.15</radius>
              <length>0.5</length>
            </cylinder>
          </geometry>
        </collision>
        <visual name="obstacle_6_visual">
          <pose>-2.85 -1 0.25 0 0 0</pose>
          <geometry>
            <cylinder>
              <radius>0.15</radius>
              <length>0.5</length>
            </cylinder>
          </geometry>
          <material>
          <script>
            <uri>file://media/materials/scripts/Gazebo.material</uri>
            <name>Gazebo/Black</name>
          </script>
          </material>
        </visual>
      </link>
      <link name="obstacle_7">
        <collision name="obstacle_7_collision">
          <pose>-2.85 7 0.25 0 0 0</pose>
          <geometry>
            <cylinder>
              <radius>0.15</radius>
              <length>0.5</length>
            </cylinder>
          </geometry>
        </collision>
        <visual name="obstacle_7_visual">
          <pose>-2.85 7 0.25 0 0 0</pose>
          <geometry>
            <cylinder>
              <radius>0.15</radius>
              <length>0.5</length>
            </cylinder>
          </geometry>
          <material>
          <script>
            <uri>file://media/materials/scripts/Gazebo.material</uri>
            <name>Gazebo/Black</name>
          </script>
          </material>
        </visual>
      </link>
    </model>
    <gui fullscreen='0'>
      <camera name='user_camera'>
        <pose frame=''>-3.71122 10.3684 18.9691 0 1.09965 -0.599805</pose>
        <view_controller>orbit</view_controller>
        <projection_type>perspective</projection_type>
      </camera>
    </gui>
    <physics:ode>
      <stepTime>0.001</stepTime>
      <gravity>0 0 -9.8</gravity>
      <cfm>0.0000000001</cfm>
      <erp>0.2</erp>
      <quickStep>true</quickStep>
      <quickStepIters>1000</quickStepIters>
      <quickStepW>1.3</quickStepW>
      <contactMaxCorrectingVel>100.0</contactMaxCorrectingVel>
      <contactSurfaceLayer>0.001</contactSurfaceLayer>
    </physics:ode>
  </world>
</sdf>
