<sdf version='1.6'>
  <world name='default'>
    <include>
      <uri>model://ground_plane</uri>
    </include>
    <include>
      <uri>model://sun</uri>
    </include>
    <model name='wall'>
      <static>false</static>
      <link name="wall_left">
        <pose>1.0 0.1 1.0 0 0 0</pose>
        <visual name='wall_left_visual'>
          <geometry>
            <box>
              <size>2.0 0.2 2.0</size>
            </box>
          </geometry>
          <material>
            <script>
              <uri>file://media/materials/scripts/gazebo.material</uri>
              <name>Gazebo/Grey</name>
            </script>
            <ambient>1 1 1 1</ambient>
          </material>
        </visual>
        <collision name='wall_left_collision'>
          <geometry>
            <box>
              <size>2.0 0.2 2.0</size>
            </box>
          </geometry>
        </collision>
      </link>
      <link name="wall_right">
        <pose>4.0 0.1 1.0 0 0 0</pose>
        <visual name='wall_right_visual'>
          <geometry>
            <box>
              <size>2.0 0.2 2.0</size>
            </box>
          </geometry>
          <material>
            <script>
              <uri>file://media/materials/scripts/gazebo.material</uri>
              <name>Gazebo/Grey</name>
            </script>
            <ambient>1 1 1 1</ambient>
          </material>
        </visual>
        <collision name='wall_right_collision'>
          <geometry>
            <box>
              <size>2.0 0.2 2.0</size>
            </box>
          </geometry>
        </collision>
      </link>
      <link name="single_door">
        <pose>2.5 0.1 1.0 0 0 0</pose>
        <inertial>
          <origin xyz="2.5 0.1 1.0"/>
          <mass value="5.0"/>
          <inertia ixx="1.0" ixy="0.0" ixz="0.0" iyy="100.0" iyz="0.0" izz="1.0"/>
        </inertial>
        <visual name="door_visual">
          <geometry>
            <box>
              <size>1.0 0.2 2.0</size>
            </box>
          </geometry>
          <material>
            <script>
              <uri>file://media/materials/scripts/gazebo.material</uri>
              <name>Gazebo/Red</name>
            </script>
          </material>
        </visual>
        <collision name="door_collision">
          <geometry>
            <box>
              <size>1.0 0.2 2.0</size>
            </box>
          </geometry>
        </collision>
      </link>
      <joint name="wall_door" type="revolute">
        <parent link="wall_left"/>
        <child link="single_door"/>
        <axis xyz="0 0 1"/>
        <origin xyz="2.0 0.2 0.0" rpy="0 0 0"/>
        <limit effort="15.0" lower="0.0" upper="1.57" velocity="1"/>
      </joint>
    </model>
  </world>
</sdf>
